[2022-12-26 19:37:23,988] {taskinstance.py:1159} INFO - Dependencies all met for <TaskInstance: podcast_summary2.create_table_postgres manual__2022-12-26T19:37:23.285671+00:00 [queued]>
[2022-12-26 19:37:24,001] {taskinstance.py:1159} INFO - Dependencies all met for <TaskInstance: podcast_summary2.create_table_postgres manual__2022-12-26T19:37:23.285671+00:00 [queued]>
[2022-12-26 19:37:24,002] {taskinstance.py:1356} INFO - 
--------------------------------------------------------------------------------
[2022-12-26 19:37:24,002] {taskinstance.py:1357} INFO - Starting attempt 1 of 1
[2022-12-26 19:37:24,003] {taskinstance.py:1358} INFO - 
--------------------------------------------------------------------------------
[2022-12-26 19:37:24,021] {taskinstance.py:1377} INFO - Executing <Task(PostgresOperator): create_table_postgres> on 2022-12-26 19:37:23.285671+00:00
[2022-12-26 19:37:24,026] {standard_task_runner.py:52} INFO - Started process 6501 to run task
[2022-12-26 19:37:24,029] {standard_task_runner.py:79} INFO - Running: ['***', 'tasks', 'run', 'podcast_summary2', 'create_table_postgres', 'manual__2022-12-26T19:37:23.285671+00:00', '--job-id', '22', '--raw', '--subdir', 'DAGS_FOLDER/podcast_summer/podcast_summer2.py', '--cfg-path', '/tmp/tmp7e_dc6sh', '--error-file', '/tmp/tmpizi0tpvg']
[2022-12-26 19:37:24,031] {standard_task_runner.py:80} INFO - Job 22: Subtask create_table_postgres
[2022-12-26 19:37:24,091] {task_command.py:369} INFO - Running <TaskInstance: podcast_summary2.create_table_postgres manual__2022-12-26T19:37:23.285671+00:00 [running]> on host 29349a459c56
[2022-12-26 19:37:24,171] {taskinstance.py:1571} INFO - Exporting the following env vars:
AIRFLOW_CTX_DAG_OWNER=***
AIRFLOW_CTX_DAG_ID=podcast_summary2
AIRFLOW_CTX_TASK_ID=create_table_postgres
AIRFLOW_CTX_EXECUTION_DATE=2022-12-26T19:37:23.285671+00:00
AIRFLOW_CTX_TRY_NUMBER=1
AIRFLOW_CTX_DAG_RUN_ID=manual__2022-12-26T19:37:23.285671+00:00
[2022-12-26 19:37:24,183] {base.py:68} INFO - Using connection ID 'postgres_localhost' for task execution.
[2022-12-26 19:37:26,226] {taskinstance.py:1889} ERROR - Task failed with exception
Traceback (most recent call last):
  File "/home/airflow/.local/lib/python3.7/site-packages/airflow/providers/postgres/operators/postgres.py", line 92, in execute
    self.hook.run(self.sql, self.autocommit, parameters=self.parameters)
  File "/home/airflow/.local/lib/python3.7/site-packages/airflow/hooks/dbapi.py", line 181, in run
    with closing(self.get_conn()) as conn:
  File "/home/airflow/.local/lib/python3.7/site-packages/airflow/providers/postgres/hooks/postgres.py", line 113, in get_conn
    self.conn = psycopg2.connect(**conn_args)
  File "/home/airflow/.local/lib/python3.7/site-packages/psycopg2/__init__.py", line 122, in connect
    conn = _connect(dsn, connection_factory=connection_factory, **kwasync)
psycopg2.OperationalError: connection to server at "host.docker.internal" (192.168.65.2), port 5432 failed: Connection refused
	Is the server running on that host and accepting TCP/IP connections?

[2022-12-26 19:37:26,236] {taskinstance.py:1400} INFO - Marking task as FAILED. dag_id=podcast_summary2, task_id=create_table_postgres, execution_date=20221226T193723, start_date=20221226T193723, end_date=20221226T193726
[2022-12-26 19:37:26,251] {standard_task_runner.py:97} ERROR - Failed to execute job 22 for task create_table_postgres (connection to server at "host.docker.internal" (192.168.65.2), port 5432 failed: Connection refused
	Is the server running on that host and accepting TCP/IP connections?
; 6501)
[2022-12-26 19:37:26,289] {local_task_job.py:156} INFO - Task exited with return code 1
[2022-12-26 19:37:26,334] {local_task_job.py:273} INFO - 0 downstream tasks scheduled from follow-on schedule check
