[2022-12-26 16:45:09,909] {taskinstance.py:1159} INFO - Dependencies all met for <TaskInstance: podcast_summary2.create_table_postgres scheduled__2022-12-25T00:00:00+00:00 [queued]>
[2022-12-26 16:45:09,921] {taskinstance.py:1159} INFO - Dependencies all met for <TaskInstance: podcast_summary2.create_table_postgres scheduled__2022-12-25T00:00:00+00:00 [queued]>
[2022-12-26 16:45:09,921] {taskinstance.py:1356} INFO - 
--------------------------------------------------------------------------------
[2022-12-26 16:45:09,922] {taskinstance.py:1357} INFO - Starting attempt 1 of 1
[2022-12-26 16:45:09,922] {taskinstance.py:1358} INFO - 
--------------------------------------------------------------------------------
[2022-12-26 16:45:09,939] {taskinstance.py:1377} INFO - Executing <Task(PostgresOperator): create_table_postgres> on 2022-12-25 00:00:00+00:00
[2022-12-26 16:45:09,945] {standard_task_runner.py:52} INFO - Started process 430 to run task
[2022-12-26 16:45:09,948] {standard_task_runner.py:79} INFO - Running: ['***', 'tasks', 'run', 'podcast_summary2', 'create_table_postgres', 'scheduled__2022-12-25T00:00:00+00:00', '--job-id', '8', '--raw', '--subdir', 'DAGS_FOLDER/podcast_summer/podcast_summer2.py', '--cfg-path', '/tmp/tmp6oxuk4w4', '--error-file', '/tmp/tmp9xe99nmw']
[2022-12-26 16:45:09,950] {standard_task_runner.py:80} INFO - Job 8: Subtask create_table_postgres
[2022-12-26 16:45:10,015] {task_command.py:369} INFO - Running <TaskInstance: podcast_summary2.create_table_postgres scheduled__2022-12-25T00:00:00+00:00 [running]> on host 08fab8d1a565
[2022-12-26 16:45:10,102] {taskinstance.py:1571} INFO - Exporting the following env vars:
AIRFLOW_CTX_DAG_OWNER=***
AIRFLOW_CTX_DAG_ID=podcast_summary2
AIRFLOW_CTX_TASK_ID=create_table_postgres
AIRFLOW_CTX_EXECUTION_DATE=2022-12-25T00:00:00+00:00
AIRFLOW_CTX_TRY_NUMBER=1
AIRFLOW_CTX_DAG_RUN_ID=scheduled__2022-12-25T00:00:00+00:00
[2022-12-26 16:45:10,126] {taskinstance.py:1889} ERROR - Task failed with exception
Traceback (most recent call last):
  File "/home/airflow/.local/lib/python3.7/site-packages/airflow/providers/postgres/operators/postgres.py", line 92, in execute
    self.hook.run(self.sql, self.autocommit, parameters=self.parameters)
  File "/home/airflow/.local/lib/python3.7/site-packages/airflow/hooks/dbapi.py", line 181, in run
    with closing(self.get_conn()) as conn:
  File "/home/airflow/.local/lib/python3.7/site-packages/airflow/providers/postgres/hooks/postgres.py", line 86, in get_conn
    conn = deepcopy(self.connection or self.get_connection(conn_id))
  File "/home/airflow/.local/lib/python3.7/site-packages/airflow/hooks/base.py", line 67, in get_connection
    conn = Connection.get_connection_from_secrets(conn_id)
  File "/home/airflow/.local/lib/python3.7/site-packages/airflow/models/connection.py", line 430, in get_connection_from_secrets
    raise AirflowNotFoundException(f"The conn_id `{conn_id}` isn't defined")
airflow.exceptions.AirflowNotFoundException: The conn_id `postgres_default` isn't defined
[2022-12-26 16:45:10,131] {taskinstance.py:1400} INFO - Marking task as FAILED. dag_id=podcast_summary2, task_id=create_table_postgres, execution_date=20221225T000000, start_date=20221226T164509, end_date=20221226T164510
[2022-12-26 16:45:10,143] {standard_task_runner.py:97} ERROR - Failed to execute job 8 for task create_table_postgres (The conn_id `postgres_default` isn't defined; 430)
[2022-12-26 16:45:10,161] {local_task_job.py:156} INFO - Task exited with return code 1
[2022-12-26 16:45:10,204] {local_task_job.py:273} INFO - 0 downstream tasks scheduled from follow-on schedule check
[2022-12-26 19:42:46,012] {taskinstance.py:1159} INFO - Dependencies all met for <TaskInstance: podcast_summary2.create_table_postgres scheduled__2022-12-25T00:00:00+00:00 [queued]>
[2022-12-26 19:42:46,022] {taskinstance.py:1159} INFO - Dependencies all met for <TaskInstance: podcast_summary2.create_table_postgres scheduled__2022-12-25T00:00:00+00:00 [queued]>
[2022-12-26 19:42:46,022] {taskinstance.py:1356} INFO - 
--------------------------------------------------------------------------------
[2022-12-26 19:42:46,023] {taskinstance.py:1357} INFO - Starting attempt 1 of 1
[2022-12-26 19:42:46,023] {taskinstance.py:1358} INFO - 
--------------------------------------------------------------------------------
[2022-12-26 19:42:46,040] {taskinstance.py:1377} INFO - Executing <Task(PostgresOperator): create_table_postgres> on 2022-12-25 00:00:00+00:00
[2022-12-26 19:42:46,045] {standard_task_runner.py:52} INFO - Started process 272 to run task
[2022-12-26 19:42:46,047] {standard_task_runner.py:79} INFO - Running: ['***', 'tasks', 'run', 'podcast_summary2', 'create_table_postgres', 'scheduled__2022-12-25T00:00:00+00:00', '--job-id', '2', '--raw', '--subdir', 'DAGS_FOLDER/podcast_summer/podcast_summer2.py', '--cfg-path', '/tmp/tmpla7lonwe', '--error-file', '/tmp/tmp47ojs00t']
[2022-12-26 19:42:46,048] {standard_task_runner.py:80} INFO - Job 2: Subtask create_table_postgres
[2022-12-26 19:42:46,154] {task_command.py:369} INFO - Running <TaskInstance: podcast_summary2.create_table_postgres scheduled__2022-12-25T00:00:00+00:00 [running]> on host b1dad8c5c2ae
[2022-12-26 19:42:46,215] {taskinstance.py:1571} INFO - Exporting the following env vars:
AIRFLOW_CTX_DAG_OWNER=***
AIRFLOW_CTX_DAG_ID=podcast_summary2
AIRFLOW_CTX_TASK_ID=create_table_postgres
AIRFLOW_CTX_EXECUTION_DATE=2022-12-25T00:00:00+00:00
AIRFLOW_CTX_TRY_NUMBER=1
AIRFLOW_CTX_DAG_RUN_ID=scheduled__2022-12-25T00:00:00+00:00
[2022-12-26 19:42:46,236] {taskinstance.py:1889} ERROR - Task failed with exception
Traceback (most recent call last):
  File "/home/airflow/.local/lib/python3.7/site-packages/airflow/providers/postgres/operators/postgres.py", line 92, in execute
    self.hook.run(self.sql, self.autocommit, parameters=self.parameters)
  File "/home/airflow/.local/lib/python3.7/site-packages/airflow/hooks/dbapi.py", line 181, in run
    with closing(self.get_conn()) as conn:
  File "/home/airflow/.local/lib/python3.7/site-packages/airflow/providers/postgres/hooks/postgres.py", line 86, in get_conn
    conn = deepcopy(self.connection or self.get_connection(conn_id))
  File "/home/airflow/.local/lib/python3.7/site-packages/airflow/hooks/base.py", line 67, in get_connection
    conn = Connection.get_connection_from_secrets(conn_id)
  File "/home/airflow/.local/lib/python3.7/site-packages/airflow/models/connection.py", line 430, in get_connection_from_secrets
    raise AirflowNotFoundException(f"The conn_id `{conn_id}` isn't defined")
airflow.exceptions.AirflowNotFoundException: The conn_id `postgres_localhost` isn't defined
[2022-12-26 19:42:46,239] {taskinstance.py:1400} INFO - Marking task as FAILED. dag_id=podcast_summary2, task_id=create_table_postgres, execution_date=20221225T000000, start_date=20221226T194246, end_date=20221226T194246
[2022-12-26 19:42:46,248] {standard_task_runner.py:97} ERROR - Failed to execute job 2 for task create_table_postgres (The conn_id `postgres_localhost` isn't defined; 272)
[2022-12-26 19:42:46,259] {local_task_job.py:156} INFO - Task exited with return code 1
[2022-12-26 19:42:46,294] {local_task_job.py:273} INFO - 0 downstream tasks scheduled from follow-on schedule check
